Workbook

Sheet Лист1
A1: Дата | B1: Территория | C1: Товарооборот, шт | D1: Товарооборот, руб | E1: Количество складов | F1: Количество заказов | G1: Количество клиентов | H1: Товарооборот на склад | I1: Неделя
A2: 43982 | B2: Самара | C2: 7944 | D2: 623971.5 | E2: =SUMIFS(Лист2!$C:$C, Лист2!$A:$A, $A2, Лист2!$B:$B, $B2) -> 15 | F2: =SUMIFS(Лист2!$D:$D, Лист2!$A:$A, $A2, Лист2!$B:$B, $B2) -> 441 | G2: =SUMIFS(Лист2!$E:$E, Лист2!$A:$A, $A2, Лист2!$B:$B, $B2) -> 368 | H2: =IFERROR(Таблица1[[#This Row],[Товарооборот, руб]]/Таблица1[[#This Row],[Количество складов]],0) -> 41598.1 | I2: =INT((A2-DATE(YEAR(A2),1,1)+WEEKDAY(A2,2)+6)/7) -> 23
A3: 43981 | B3: Самара | C3: 10029 | D3: 787101 | E3: =SUMIFS(Лист2!$C:$C, Лист2!$A:$A, $A3, Лист2!$B:$B, $B3) -> 15 | F3: =SUMIFS(Лист2!$D:$D, Лист2!$A:$A, $A3, Лист2!$B:$B, $B3) -> 490 | G3: =SUMIFS(Лист2!$E:$E, Лист2!$A:$A, $A3, Лист2!$B:$B, $B3) -> 409 | H3: =IFERROR(Таблица1[[#This Row],[Товарооборот, руб]]/Таблица1[[#This Row],[Количество складов]],0) -> 52473.4 | I3: =INT((A3-DATE(YEAR(A3),1,1)+WEEKDAY(A3,2)+6)/7) -> 23
A4: 43979 | B4: Самара | C4: 8536.5 | D4: 643944 | E4: =SUMIFS(Лист2!$C:$C, Лист2!$A:$A, $A4, Лист2!$B:$B, $B4) -> 15 | F4: =SUMIFS(Лист2!$D:$D, Лист2!$A:$A, $A4, Лист2!$B:$B, $B4) -> 464 | G4: =SUMIFS(Лист2!$E:$E, Лист2!$A:$A, $A4, Лист2!$B:$B, $B4) -> 390 | H4: =IFERROR(Таблица1[[#This Row],[Товарооборот, руб]]/Таблица1[[#This Row],[Количество складов]],0) -> 42929.6 | I4: =INT((A4-DATE(YEAR(A4),1,1)+WEEKDAY(A4,2)+6)/7) -> 22
A5: 43967 | B5: Кемерово | C5: 38947.5 | D5: 3395892 | E5: =SUMIFS(Лист2!$C:$C, Лист2!$A:$A, $A5, Лист2!$B:$B, $B5) -> 21 | F5: =SUMIFS(Лист2!$D:$D, Лист2!$A:$A, $A5, Лист2!$B:$B, $B5) -> 2145 | G5: =SUMIFS(Лист2!$E:$E, Лист2!$A:$A, $A5, Лист2!$B:$B, $B5) -> 1947 | H5: =IFERROR(Таблица1[[#This Row],[Товарооборот, руб]]/Таблица1[[#This Row],[Количество складов]],0) -> 161709.14 | I5: =INT((A5-DATE(YEAR(A5),1,1)+WEEKDAY(A5,2)+6)/7) -> 21
A6: 43970 | B6: Кемерово | C6: 31842 | D6: 2771116.5 | E6: =SUMIFS(Лист2!$C:$C, Лист2!$A:$A, $A6, Лист2!$B:$B, $B6) -> 21 | F6: =SUMIFS(Лист2!$D:$D, Лист2!$A:$A, $A6, Лист2!$B:$B, $B6) -> 1860 | G6: =SUMIFS(Лист2!$E:$E, Лист2!$A:$A, $A6, Лист2!$B:$B, $B6) -> 1704 | H6: =IFERROR(Таблица1[[#This Row],[Товарооборот, руб]]/Таблица1[[#This Row],[Количество складов]],0) -> 131957.93 | I6: =INT((A6-DATE(YEAR(A6),1,1)+WEEKDAY(A6,2)+6)/7) -> 21
A7: 43968 | B7: Кемерово | C7: 32023.5 | D7: 2882458.5 | E7: =SUMIFS(Лист2!$C:$C, Лист2!$A:$A, $A7, Лист2!$B:$B, $B7) -> 21 | F7: =SUMIFS(Лист2!$D:$D, Лист2!$A:$A, $A7, Лист2!$B:$B, $B7) -> 1874 | G7: =SUMIFS(Лист2!$E:$E, Лист2!$A:$A, $A7, Лист2!$B:$B, $B7) -> 1705 | H7: =IFERROR(Таблица1[[#This Row],[Товарооборот, руб]]/Таблица1[[#This Row],[Количество складов]],0) -> 137259.93 | I7: =INT((A7-DATE(YEAR(A7),1,1)+WEEKDAY(A7,2)+6)/7) -> 21
A8: 43960 | B8: Кемерово | C8: 31147.5 | D8: 2831019 | E8: =SUMIFS(Лист2!$C:$C, Лист2!$A:$A, $A8, Лист2!$B:$B, $B8) -> 21 | F8: =SUMIFS(Лист2!$D:$D, Лист2!$A:$A, $A8, Лист2!$B:$B, $B8) -> 1735 | G8: =SUMIFS(Лист2!$E:$E, Лист2!$A:$A, $A8, Лист2!$B:$B, $B8) -> 1568 | H8: =IFERROR(Таблица1[[#This Row],[Товарооборот, руб]]/Таблица1[[#This Row],[Количество складов]],0) -> 134810.43 | I8: =INT((A8-DATE(YEAR(A8),1,1)+WEEKDAY(A8,2)+6)/7) -> 20
A9: 43955 | B9: Кемерово | C9: 25566 | D9: 2372310 | E9: =SUMIFS(Лист2!$C:$C, Лист2!$A:$A, $A9, Лист2!$B:$B, $B9) -> 20 | F9: =SUMIFS(Лист2!$D:$D, Лист2!$A:$A, $A9, Лист2!$B:$B, $B9) -> 1519 | G9: =SUMIFS(Лист2!$E:$E, Лист2!$A:$A, $A9, Лист2!$B:$B, $B9) -> 1372 | H9: =IFERROR(Таблица1[[#This Row],[Товарооборот, руб]]/Таблица1[[#This Row],[Количество складов]],0) -> 118615.5 | I9: =INT((A9-DATE(YEAR(A9),1,1)+WEEKDAY(A9,2)+6)/7) -> 18
A10: 43950 | B10: Кемерово | C10: 29319 | D10: 2623480.5 | E10: =SUMIFS(Лист2!$C:$C, Лист2!$A:$A, $A10, Лист2!$B:$B, $B10) -> 18 | F10: =SUMIFS(Лист2!$D:$D, Лист2!$A:$A, $A10, Лист2!$B:$B, $B10) -> 1684 | G10: =SUMIFS(Лист2!$E:$E, Лист2!$A:$A, $A10, Лист2!$B:$B, $B10) -> 1528 | H10: =IFERROR(Таблица1[[#This Row],[Товарооборот, руб]]/Таблица1[[#This Row],[Количество складов]],0) -> 145748.92 | I10: =INT((A10-DATE(YEAR(A10),1,1)+WEEKDAY(A10,2)+6)/7) -> 18
A11: 43953 | B11: Кемерово | C11: 29031 | D11: 2711247 | E11: =SUMIFS(Лист2!$C:$C, Лист2!$A:$A, $A11, Лист2!$B:$B, $B11) -> 18 | F11: =SUMIFS(Лист2!$D:$D, Лист2!$A:$A, $A11, Лист2!$B:$B, $B11) -> 1708 | G11: =SUMIFS(Лист2!$E:$E, Лист2!$A:$A, $A11, Лист2!$B:$B, $B11) -> 1534 | H11: =IFERROR(Таблица1[[#This Row],[Товарооборот, руб]]/Таблица1[[#This Row],[Количество складов]],0) -> 150624.83 | I11: =INT((A11-DATE(YEAR(A11),1,1)+WEEKDAY(A11,2)+6)/7) -> 19
A12: 43977 | B12: Кемерово | C12: 33423 | D12: 2970330 | E12: =SUMIFS(Лист2!$C:$C, Лист2!$A:$A, $A12, Лист2!$B:$B, $B12) -> 20 | F12: =SUMIFS(Лист2!$D:$D, Лист2!$A:$A, $A12, Лист2!$B:$B, $B12) -> 2044 | G12: =SUMIFS(Лист2!$E:$E, Лист2!$A:$A, $A12, Лист2!$B:$B, $B12) -> 1863 | H12: =IFERROR(Таблица1[[#This Row],[Товарооборот, руб]]/Таблица1[[#This Row],[Количество складов]],0) -> 148516.5 | I12: =INT((A12-DATE(YEAR(A12),1,1)+WEEKDAY(A12,2)+6)/7) -> 22
A13: 43952 | B13: Кемерово | C13: 32487 | D13: 3031254 | E13: =SUMIFS(Лист2!$C:$C, Лист2!$A:$A, $A13, Лист2!$B:$B, $B13) -> 18 | F13: =SUMIFS(Лист2!$D:$D, Лист2!$A:$A, $A13, Лист2!$B:$B, $B13) -> 1826 | G13: =SUMIFS(Лист2!$E:$E, Лист2!$A:$A, $A13, Лист2!$B:$B, $B13) -> 1633 | H13: =IFERROR(Таблица1[[#This Row],[Товарооборот, руб]]/Таблица1[[#This Row],[Количество складов]],0) -> 168403 | I13: =INT((A13-DATE(YEAR(A13),1,1)+WEEKDAY(A13,2)+6)/7) -> 18
... A505: 43983 | B505: Новосибирск | C505: 14238 | D505: 1293219 | E505: =SUMIFS(Лист2!$C:$C, Лист2!$A:$A, $A505, Лист2!$B:$B, $B505) -> 18 | F505: =SUMIFS(Лист2!$D:$D, Лист2!$A:$A, $A505, Лист2!$B:$B, $B505) -> 923 | G505: =SUMIFS(Лист2!$E:$E, Лист2!$A:$A, $A505, Лист2!$B:$B, $B505) -> 824 | H505: =IFERROR(Таблица1[[#This Row],[Товарооборот, руб]]/Таблица1[[#This Row],[Количество складов]],0) -> 71845.5 | I505: =INT((A505-DATE(YEAR(A505),1,1)+WEEKDAY(A505,2)+6)/7) -> 22

Sheet Лист2
A1: Дата | B1: Территория | C1: Количество складов | D1: Количество заказов | E1: Количество клиентов
A2: 43949 | B2: Волгоград | C2: 36 | D2: 4923 | E2: 4560
A3: 43949 | B3: Екатеринбург | C3: 31 | D3: 5465 | E3: 5096
A4: 43949 | B4: Казань | C4: 19 | D4: 1846 | E4: 1681
A5: 43949 | B5: Кемерово | C5: 18 | D5: 1539 | E5: 1404
A6: 43949 | B6: Краснодар | C6: 18 | D6: 1505 | E6: 1368
A7: 43949 | B7: Москва Восток | C7: 54 | D7: 12306 | E7: 11532
A8: 43949 | B8: Москва Запад | C8: 59 | D8: 12943 | E8: 12072
A9: 43949 | B9: Нижний Новгород | C9: 17 | D9: 1439 | E9: 1265
A10: 43949 | B10: Новосибирск | C10: 15 | D10: 636 | E10: 547
A11: 43949 | B11: Пермь | C11: 15 | D11: 780 | E11: 690
A12: 43949 | B12: Санкт-Петербург Север | C12: 125 | D12: 20914 | E12: 19479
A13: 43949 | B13: Санкт-Петербург Юг | C13: 128 | D13: 16450 | E13: 15320
... A505: 43983 | B505: Уфа | C505: 6 | D505: 237 | E505: 175

Sheet МАССИВ
A6: Названия строк | B6: Сумма по полю Товарооборот, руб | C6: Сумма по полю Товарооборот на склад
A7: Волгоград | B7: 218000127 | C7: 6029485.6
A8: 18 | B8: 32155976 | C8: 893221.54
A9: 19 | B9: 38283948 | C9: 1063443
A10: 20 | B10: 44295501 | C10: 1230430.6
A11: 21 | B11: 43412614 | C11: 1205906 | H11: Неделя | I11: 23
A12: 22 | B12: 44252853 | C12: 1214883.6
A13: 23 | B13: 15599235 | C13: 421600.95 | E13: Названия строк | F13: Сумма по полю Товарооборот, руб | H13: Названия строк | I13: Сумма по полю Товарооборот на склад
A14: Екатеринбург | B14: 2.43409e+08 | C14: 7851903.3 | E14: Волгоград | F14: 0.043930743 | H14: Волгоград | I14: 0.065514473
A15: 18 | B15: 36903144 | C15: 1190424 | E15: Екатеринбург | F15: 0.049051065 | H15: Екатеринбург | I15: 0.083599009
A16: 19 | B16: 44942216 | C16: 1449748.9 | E16: Казань | F16: 0.024299498 | H16: Казань | I16: 0.058463202
A17: 20 | B17: 46680258 | C17: 1505814.8 | E17: Кемерово | F17: 0.020488951 | H17: Кемерово | I17: 0.056177104
A18: 21 | B18: 49429707 | C18: 1594506.7 | E18: Краснодар | F18: 0.017302774 | H18: Краснодар | I18: 0.044027891
A19: 22 | B19: 48776325 | C19: 1573429.8 | E19: Москва Восток | F19: 0.14874466 | H19: Москва Восток | I19: 0.12911911
A20: 23 | B20: 16677354 | C20: 537979.16 | E20: Москва Запад | F20: 0.15600381 | H20: Москва Запад | I20: 0.12145151
A21: Казань | B21: 120582837 | C21: 5758962.4 | E21: Нижний Новгород | F21: 0.019263478 | H21: Нижний Новгород | I21: 0.051638882
A22: 18 | B22: 15455601 | C22: 787230.56 | E22: Новосибирск | F22: 0.0082691777 | H22: Новосибирск | I22: 0.027596032
A23: 19 | B23: 19792776 | C23: 967697.15 | E23: Пермь | F23: 0.0098346447 | H23: Пермь | I23: 0.037014712
A24: 20 | B24: 23301546 | C24: 1109597.4 | E24: Ростов-на-Дону | F24: 0.0070161281 | H24: Ростов-на-Дону | I24: 0.028610849
A25: 21 | B25: 26901111 | C25: 1281005.3 | E25: Самара | F25: 0.0006735906 | H25: Самара | I25: 0.014618195
A26: 22 | B26: 26681208 | C26: 1237207.6 | E26: Санкт-Петербург Север | F26: 0.27823941 | H26: Санкт-Петербург Север | I26: 0.10746167
A27: 23 | B27: 8450595 | C27: 376224.37 | E27: Санкт-Петербург Юг | F27: 0.20869355 | H27: Санкт-Петербург Юг | I27: 0.078362512
A28: Кемерово | B28: 1.0167354e+08 | C28: 5019070.5 | E28: Тольятти | F28: 0.0066918904 | H28: Тольятти | I28: 0.035833943
A29: 18 | B29: 13255828 | C29: 715018 | E29: Томск | F29: 0.00017792061 | H29: Томск | I29: 0.0085275846
A30: 19 | B30: 18588316 | C30: 926390.76 | E30: Тюмень | F30: 0.001141424 | H30: Тюмень | I30: 0.039840911
A31: 20 | B31: 19937352 | C31: 949397.71 | E31: Уфа | F31: 0.00017728009 | H31: Уфа | I31: 0.012142411
A32: 21 | B32: 20990829 | C32: 1007126.6 | E32: Общий итог | F32: 1 | H32: Общий итог | I32: 1
A33: 22 | B33: 21505530 | C33: 1059624.7
A34: 23 | B34: 7395679.5 | C34: 361512.8
A35: Краснодар | B35: 85862582 | C35: 4464328.5
A36: 18 | B36: 12522244 | C36: 672626.86
A37: 19 | B37: 14837754 | C37: 780934.42 | E37: Названия строк | F37: Сумма по полю Товарооборот, руб | G37: Сумма по полю Товарооборот на склад
A38: 20 | B38: 16686338 | C38: 878228.29 | E38: 18 | F38: 718517823 | G38: 12905075
A39: 21 | B39: 17578258 | C39: 918558.86 | E39: 19 | F39: 9.3823789e+08 | G39: 16919927
A40: 22 | B40: 18438328 | C40: 930650.34 | E40: 20 | F40: 9.6042076e+08 | G40: 17689484
A41: 23 | B41: 5799658.5 | C41: 283329.77 | E41: 21 | F41: 9.8074767e+08 | G41: 18470456
A42: Москва Восток | B42: 738124428 | C42: 13668971 | E42: 22 | F42: 1.0454149e+09 | G42: 19942935
A43: 18 | B43: 1.0936548e+08 | C43: 2025286.6 | E43: 23 | F43: 3.1902013e+08 | G43: 6435233.7
A44: 19 | B44: 1.4843191e+08 | C44: 2748739.1 | E44: Общий итог | F44: 4.9623592e+09 | G44: 92363110
A45: 20 | B45: 139422975 | C45: 2581906.9
...
